<mujoco>
    <include file="base_env.xml"></include>
    <asset>
        <texture builtin="flat" type="2d" name="box_tex" height="32" width="32" />
        <material name="box_mat" specular="0.5" shininess="0.2" reflectance="0" texture="box_tex" />
        <texture builtin="flat" type="2d" name="box_int_tex" height="32" width="32" />
        <material name="box_int_mat" specular="0.5" shininess="0.2" reflectance="0" texture="box_int_tex" />
        <texture builtin="flat" type="2d" name="lid_tex" height="32" width="32" />
        <material name="lid_mat" specular="0.5" shininess="0.2" reflectance="0" texture="lid_tex" />
        <texture builtin="flat" type="2d" name="lid_handle_tex" height="32" width="32" />
        <material name="lid_handle_mat" specular="0.5" shininess="0.2" reflectance="0" texture="lid_handle_tex" />
        <texture builtin="flat" type="2d" name="marker0_tex" height="32" width="32" />
        <material name="marker0_mat" specular="0.5" shininess="0.2" reflectance="0" texture="marker0_tex" />
        <texture builtin="flat" type="2d" name="cube0_tex" height="32" width="32" />
        <material name="cube0_mat" specular="0.5" shininess="0.2" reflectance="0" texture="cube0_tex" />
        <texture builtin="flat" type="2d" name="cube1_tex" height="32" width="32" />
        <material name="cube1_mat" specular="0.5" shininess="0.2" reflectance="0" texture="cube1_tex" />
    </asset>

    <worldbody>
        <body mocap="true" name="box" pos="-0.4 -0.1 0.002">
            <geom name="box_bottom" size="0.1025 0.105 0.001" type="box"  material="box_mat" />
            <geom name="box_int_bottom" size="0.1025 0.105 0.001" type="box"  material="box_int_mat" pos="0 0 0.001" />
            <geom name="box_side0" pos="0.0 0.105 0.0325" size="0.1025 0.0325 0.001" euler="1.57079632679 0 0" type="box"  material="box_mat" />
            <geom name="box_int_side0" pos="0.0 0.104 0.0325" size="0.1025 0.0325 0.001" euler="1.57079632679 0 0" type="box"  material="box_int_mat" />
            <geom name="box_side1" pos="0.0 -0.105 0.0325" size="0.1025 0.0325 0.001" euler="1.57079632679 0 0" type="box"  material="box_mat" />
            <geom name="box_int_side1" pos="0.0 -0.104 0.0325" size="0.1025 0.0325 0.001" euler="1.57079632679 0 0" type="box"  material="box_int_mat" />
            <geom name="box_side2" pos="0.1025 0.0 0.0325" size="0.0325 0.105 0.001" euler="0 1.57079632679 0" type="box"  material="box_mat" />
            <geom name="box_int_side2" pos="0.1015 0.0 0.0325" size="0.0325 0.105 0.001" euler="0 1.57079632679 0" type="box"  material="box_int_mat" />
            <geom name="box_side3" pos="-0.1025 0.0 0.0325" size="0.0325 0.105 0.001" euler="0 1.57079632679 0" type="box"  material="box_mat" />
            <geom name="box_int_side3" pos="-0.1015 0.0 0.0325" size="0.0325 0.105 0.001" euler="0 1.57079632679 0" type="box"  material="box_int_mat" />
            <geom name="box_separator" pos="0.0 0.0 0.0325" size="0.0325 0.105 0.001" euler="0 1.57079632679 0" type="box"  material="box_int_mat" />
        </body>
        <body name="lid" pos ="-0.4 -0.1 0.08">
            <joint name="lid_joint" />
            <geom name="lid_top" pos="0.0 0.0 0.0" size="0.115 0.115 0.002" type="box"  material="lid_mat" />
            <body name="lid_handle" pos="0.0 0.0 0.017">
                <geom name="lid_handle" size="0.035 0.017 0.017" type="box" material="lid_handle_mat" />
            </body>
        </body>

        <body mocap="true"  name="marker0" pos="-0.7 0.0 0.0001">
            <site name="marker0" size="0.025 0.025 0.01" pos="0.0 0.0 0.0" rgba="0 0 0 0" type="box" />
            <geom name="marker0" size="0.025 0.025 0.01" type="plane"  material="marker0_mat"  />
        </body>

        <body childclass="cube" name="cube0" pos="0.0 0.0 0.025">
            <joint name="cube0_joint" />
            <geom name="cube0" size="0.025 0.025 0.025" type="box"  material="cube0_mat" />
            <site name="cube0" size="0.025 0.025 0.025" rgba="1 0 0 0" type="sphere" />
        </body>
        <body childclass="cube" name="cube1" pos="0.0 0.0 0.025">
            <joint name="cube1_joint" />
            <geom name="cube1" size="0.025 0.025 0.025" type="box"  material="cube1_mat" />
            <site name="cube1" size="0.025 0.025 0.025" rgba="1 0 0 0" type="sphere" />
        </body>

    </worldbody>
</mujoco>
