<mujoco>
    <include file="base_env.xml"></include>

    <asset>
        <texture builtin="flat" type="2d" name="pink_cube0_tex" height="32" width="32" />
        <material name="pink_cube0_mat" specular="0.5" shininess="0.2" reflectance="0" texture="pink_cube0_tex" />
        <texture builtin="flat" type="2d" name="pink_cube1_tex" height="32" width="32" />
        <material name="pink_cube1_mat" specular="0.5" shininess="0.2" reflectance="0" texture="pink_cube1_tex" />
        <texture builtin="flat" type="2d" name="pink_cube2_tex" height="32" width="32" />
        <material name="pink_cube2_mat" specular="0.5" shininess="0.2" reflectance="0" texture="pink_cube2_tex" />
        <texture builtin="flat" type="2d" name="blue_cube0_tex" height="32" width="32" />
        <material name="blue_cube0_mat" specular="0.5" shininess="0.2" reflectance="0" texture="blue_cube0_tex" />
        <texture builtin="flat" type="2d" name="blue_cube1_tex" height="32" width="32" />
        <material name="blue_cube1_mat" specular="0.5" shininess="0.2" reflectance="0" texture="blue_cube1_tex" />
        <texture builtin="flat" type="2d" name="blue_cube2_tex" height="32" width="32" />
        <material name="blue_cube2_mat" specular="0.5" shininess="0.2" reflectance="0" texture="blue_cube2_tex" />
    </asset>

    <worldbody>
      <body childclass="cube" name="pink_cube0" pos="0 0 -2">
          <joint name="pink_cube0_joint" />
          <geom name="pink_cube0" size="0.015 0.015 0.015" type="box"  material="pink_cube0_mat" />
        <site name="pink_cube0" size="0.015 0.015 0.015" rgba="1 0 0 1" type="sphere" />
      </body>
      <body childclass="cube" name="pink_cube1" pos="0 0 -2">
          <joint name="pink_cube1_joint" />
          <geom name="pink_cube1" size="0.015 0.015 0.015" type="box"  material="pink_cube1_mat" />
          <site name="pink_cube1" size="0.015 0.015 0.015" rgba="1 0 0 1" type="sphere" />
      </body>
      <body childclass="cube" name="pink_cube2" pos="0 0 -2">
          <joint name="pink_cube2_joint" />
          <geom name="pink_cube2" size="0.015 0.015 0.015" type="box"  material="pink_cube2_mat" />
          <site name="pink_cube2" size="0.015 0.015 0.015" rgba="1 0 0 1" type="sphere" />
      </body>
      <body childclass="cube" name="blue_cube0" pos="0 0 -2">
          <joint name="blue_cube0_joint" />
          <geom name="blue_cube0" size="0.015 0.015 0.015" type="box"  material="blue_cube0_mat" />
          <site name="blue_cube0" size="0.015 0.015 0.015" rgba="1 0 0 1" type="sphere" />
      </body>
      <body childclass="cube" name="blue_cube1" pos="0 0 -2">
          <joint name="blue_cube1_joint" />
          <geom name="blue_cube1" size="0.015 0.015 0.015" type="box"  material="blue_cube1_mat" />
          <site name="blue_cube1" size="0.015 0.015 0.015" rgba="1 0 0 1" type="sphere" />
      </body>
      <body childclass="cube" name="blue_cube2" pos="0 0 -2">
          <joint name="blue_cube2_joint" />
          <geom name="blue_cube2" size="0.015 0.015 0.015" type="box"  material="blue_cube2_mat" />
          <site name="blue_cube2" size="0.015 0.015 0.015" rgba="1 0 0 1" type="sphere" />
      </body>
    </worldbody>
</mujoco>
