<mujoco>
    <worldbody>
        <body childclass="robot" name="right_base_link" pos="0.17906 -0.3825 0.78936" quat="0 0.92388 0 0.382683">
            <geom pos="0 0 0" type="mesh" rgba="0.7 0.7 0.7 1" mesh="base" name="right_base" material="arm_mat" />
            <body childclass="robot" name="right_shoulder_link" pos="0 0 0.08949928559905179">
                <inertial pos="0 0 0" mass="3.7" diaginertia="0.0149724 0.0149724 0.0104063" />
                <joint name="right_shoulder_pan_joint" pos="0 0 0" axis="0 0 1" limited="true" range="-3.14159 3.14159" />
                <geom quat="0 0 0 1" type="mesh" rgba="0.7 0.7 0.7 1" mesh="shoulder" name="right_shoulder" material="arm_mat" />
                <body name="right_upper_arm_link" pos="-4.45319e-05 0 0" quat="0.707467 0.706746 -6.71266e-06 -6.71951e-06">
                    <inertial pos="-0.212798 0 0.136" quat="0.707107 0 0.707107 0" mass="8.393" diaginertia="0.13424 0.13424 0.0151074" />
                    <joint name="right_shoulder_lift_joint" pos="0 0 0" axis="0 0 1" limited="true" range="-3.14159 3.14159" />
                    <geom pos="0 0 0.136" quat="0.5 0.5 -0.5 -0.5" type="mesh" rgba="0.7 0.7 0.7 1" mesh="upperarm" name="right_upperarm" material="arm_mat" />
                    <body name="right_forearm_link" pos="-0.425596 0 0" quat="0.999997 0.00183245 0.00155528 -8.32085e-06">
                        <inertial pos="-0.212798 0 0.0165" quat="0.707107 0 0.707107 0" mass="2.275" diaginertia="0.0312437 0.0312437 0.004095" />
                        <joint name="right_elbow_joint" pos="0 0 0" axis="0 0 1" limited="true" range="-3.14159 3.14159" />
                        <geom pos="0 0 0.0165" quat="0.5 0.5 -0.5 -0.5" type="mesh" rgba="0.7 0.7 0.7 1" mesh="forearm" name="right_forearm" material="arm_mat" />
                        <body name="right_wrist_1_link" pos="-0.392431 -0.00059445 0.111158" quat="0.999996 0.00267388 0.000339221 -1.46198e-05">
                            <inertial pos="0 0 0" quat="0.5 0.5 -0.5 0.5" mass="1.219" diaginertia="0.00342844 0.00262904 0.00262904" />
                            <joint name="right_wrist_1_joint" pos="0 0 0" axis="0 0 1" limited="true" range="-3.14159 3.14159" />
                            <geom pos="0 0 -0.093" quat="0.707107 0.707107 0 0" type="mesh" rgba="0.7 0.7 0.7 1" mesh="wrist1" name="right_wrist1" material="arm_mat" />
                            <body name="right_wrist_2_link" pos="2.94186e-05 -0.0948979 0.000126017" quat="0.707576 0.706637 -3.37154e-05 -3.37602e-05">
                                <inertial pos="0 0 0" quat="0.5 0.5 -0.5 0.5" mass="1.219" diaginertia="0.0021942 0.00178799 0.00178799" />
                                <joint name="right_wrist_2_joint" pos="0 0 0" axis="0 0 1" limited="true" range="-3.14159 3.14159" />
                                <geom pos="0 0 -0.095" type="mesh" rgba="0.7 0.7 0.7 1" mesh="wrist2" name="right_wrist2" material="arm_mat" />
                                <body name="right_wrist_3_link" pos="2.68756e-05 0.0824694 0.000106448" quat="0.707563 -0.70665 1.55001e-05 -1.55202e-05">
                                    <!-- used as the reference for mocap -->
                                    <!-- match real -->
                                    <!-- <body name="right_gripper_frame" pos="0 0 0.226" quat="1 0 0 0" /> -->
                                    <!-- reference  -->

                                    <inertial pos="0.00100986 0.00137524 0.0672963" quat="0.562577 0.42494 0.468566 0.532333" mass="1.3169" diaginertia="0.00914241 0.00648172 0.00573146" />
                                    <!-- <joint name="right_wrist_3_joint" pos="0 0 0" axis="0 0 1" limited="true" range="-3.14159 3.14159" /> -->
                                    <joint name="right_wrist_3_joint" pos="0 0 0" axis="0 0 1" limited="true" range="-6.28348 3.14159" />
                                    <geom pos="0 0 -0.0823" quat="0.707107 0.707107 0 0" type="mesh"  mesh="wrist3" name="right_wrist3" material="arm_mat6" />
                                    <!-- force torque sensor -->
                                    <geom pos="0 0 -0.004" quat="0.707107 0 0 -0.707107" type="mesh"  mesh="robotiq_ft300_coupling" name="right_robotiq_ft300_coupling" material="force_torque_mat" />
                                    <geom pos="0 0 0.0375" quat="0 0.707107 0.707107 0" type="mesh" mesh="robotiq_ft300" name="right_robotiq_ft300" material="force_torque_mat" />
                                    <!-- gripper body -->
                                    <geom pos="0 0 0.0375" quat="1 0 0 0" type="mesh" rgba="0.65 0.62 0.58 1" mesh="right_single_bracket" name="right_single_bracket" material="gripper_mat" />
                                    <body pos="0 0 0.0875" quat="1 0 0 0">
                                            <geom type="mesh" mesh="right_gripper_body" name="right_gripper_body" material="gripper_mat" />
                                            <body name="right_gripper_frame" pos="0 0 0.15"/>
                                    </body>
                                    <!-- realsense camera holder -->
                                    <geom pos="-0.002 0.026 0.188" quat="1 0 0 0" type="mesh" mesh="realsense" name="right_mounted_camera" material="mounted_camera_mat" />
                                    <!-- fingers -->
                                    <body childclass="gripper_arm" name="right_gripper_finger_1_moment_arm" pos="-0.017 0 0.1425" quat="-0.926422 0 0.376486 0">
                                        <inertial pos="0 0 0" mass="0.001" diaginertia="0.001 0.001 0.001" />
                                        <joint name="right_gripper_finger_1_joint" pos="0 0 0" axis="0 1 0" limited="true" range="0 1.3" />
                                        <geom type="mesh" rgba="0.9 0.92 0.93 1" mesh="right_moment_arm" name="right_moment_arm_1" material="gripper_arm_mat" />
                                    </body>
                                    <!-- finger 1 -->
                                    <body childclass="gripper_arm" name="right_gripper_finger_1_truss_arm" pos="-0.0075 0 0.159" quat="-0.926422 0 0.376486 0">
                                        <inertial pos="0 0 0" mass="0.001" diaginertia="0.001 0.001 0.001" />
                                        <joint name="right_gripper_finger_1_truss_arm_joint" pos="0 0 0" axis="0 1 0" limited="true" range="0 1.3" />
                                        <geom type="mesh" rgba="0.9 0.92 0.93 1" mesh="right_truss_arm" name="right_truss_arm_1" material="gripper_arm_mat" />
                                        <body childclass="gripper_finger" name="right_gripper_finger_1_tip" pos="-0.0256 0 0.04868" quat="0.926422 0 0.376486 0">
                                            <inertial pos="0.015295 0 0.0086" quat="0 0.50492 0 0.863166" mass="0.002" diaginertia="0.00200062 0.00200062 0.002" />
                                            <joint name="right_gripper_finger_1_tip_joint" pos="0 0 0" axis="0 -1 0" limited="true" range="0 1.3" />
                                            <geom type="mesh" rgba="0.9 0.92 0.93 1" mesh="right_finger_tip_1" name="right_finger_1_tip_1" material="gripper_finger_mat"  />
                                            <geom type="mesh" rgba="0.9 0.92 0.93 1" mesh="right_finger_tip_2" name="right_finger_1_tip_2" material="gripper_finger_mat" />
                                            <geom pos="0.03059 0 0.0172" type="mesh" rgba="0.25 0.25 0.25 1" mesh="right_flex_finger" name="right_flex_finger_1" material="gripper_finger_mat" />
                                        </body>
                                    </body>
                                    <!-- finger 2 -->
                                    <body childclass="gripper_arm" name="right_gripper_finger_2_moment_arm" pos="0.017 0 0.1425" quat="0 -0.376486 0 -0.926422">
                                        <inertial pos="0 0 0" mass="0.001" diaginertia="0.001 0.001 0.001" />
                                        <joint name="right_gripper_finger_2_joint" pos="0 0 0" axis="0 1 0" limited="true" range="0 1.3" />
                                        <geom type="mesh" rgba="0.9 0.92 0.93 1" mesh="right_moment_arm" name="right_moment_arm_2" material="gripper_arm_mat" />
                                    </body>
                                    <body childclass="gripper_arm" name="right_gripper_finger_2_truss_arm" pos="0.0075 0 0.159" quat="0 -0.376486 0 -0.926422">
                                        <inertial pos="0 0 0" mass="0.001" diaginertia="0.001 0.001 0.001" />
                                        <joint name="right_gripper_finger_2_truss_arm_joint" pos="0 0 0" axis="0 1 0" limited="true" range="0 1.3" />
                                        <geom type="mesh" rgba="0.9 0.92 0.93 1" mesh="right_truss_arm" name="right_truss_arm_2" material="gripper_arm_mat" />
                                        <body childclass="gripper_finger" name="right_gripper_finger_2_tip" pos="-0.0256 0 0.04868" quat="0.926422 0 0.376486 0">
                                            <inertial pos="0.015295 0 0.0086" quat="0 0.50492 0 0.863166" mass="0.002" diaginertia="0.00200062 0.00200062 0.002" />
                                            <joint name="right_gripper_finger_2_tip_joint" pos="0 0 0" axis="0 -1 0" limited="true" range="0 1.3" />
                                            <geom type="mesh" rgba="0.9 0.92 0.93 1" mesh="right_finger_tip_1" name="right_finger_2_tip_1" material="gripper_finger_mat" />
                                            <geom type="mesh" rgba="0.9 0.92 0.93 1" mesh="right_finger_tip_2" name="right_finger_2_tip_2" material="gripper_finger_mat" />
                                            <geom pos="0.03059 0 0.0172" type="mesh" rgba="0.25 0.25 0.25 1" mesh="right_flex_finger" name="right_flex_finger_2" material="gripper_finger_mat" />
                                        </body>
                                    </body>
                                </body>
                            </body>
                        </body>
                    </body>
                </body>
            </body>
        </body>

    </worldbody>
</mujoco>
