<mujoco>
    <include file="base_env.xml" />
    <size nconmax="6000" njmax="6000" nstack="50000000" />
    <asset>
        <texture builtin="flat" type="2d" name="broom_tex" height="32" width="32" />
        <material name="broom_mat" specular="0.5" shininess="0.2" reflectance="0" texture="broom_tex" />
        <texture builtin="flat" type="2d" name="marker0_tex" height="32" width="32" />
        <material name="marker0_mat" specular="0.5" shininess="0.2" reflectance="0" texture="marker0_tex" />
        <mesh name="broom" file="./meshes/broom.stl" />
    </asset>
    <size njmax="8000" nconmax="4000" />
    <worldbody>
        <body name="broom" pos="0.0 0.0 0.0">
            <joint name="broom_joint" />
            <geom name="broom" size="0.005 0.035 0.035" type="box" material="broom_mat" />
            
        </body>
        <body mocap="true" name="marker0" pos="-0.5 0.0 0.0001">
            <site name="marker0" size="0.08 0.08 0.01" pos="0.0 0.0 0.0" rgba="0 0 0 0" type="box" />
            <geom name="marker0" size="0.08 0.08 0.01" type="plane" material="marker0_mat" mass="10" />
        </body>
    </worldbody>

    <equality>
        
        <weld body1="left_gripper_sweep_frame" body2="broom" solimp="1 1 1" solref="0.001 1" />
    </equality>
    <contact>
        <exclude body1="left_gripper_finger_1_moment_arm" body2="broom" />
        <exclude body1="left_gripper_finger_1_truss_arm" body2="broom" />
        <exclude body1="left_gripper_finger_2_moment_arm" body2="broom" />
        <exclude body1="left_gripper_finger_2_truss_arm" body2="broom" />
        <exclude body1="left_gripper_finger_1_tip" body2="broom" />
        <exclude body1="left_gripper_finger_2_tip" body2="broom" />
        <exclude body1="left_gripper_finger_1_safety_shield" body2="broom" />
        <exclude body1="left_gripper_finger_2_safety_shield" body2="broom" />
    </contact>
<worldbody><body name="pile0" pos="0 0 0"><joint name="pile0_joint_x" pos="0 0 0" axis="1 0 0" type="slide" group="3" damping="0" /><joint name="pile0_joint_y" pos="0 0 0" axis="0 1 0" type="slide" group="3" damping="0" /><joint name="pile0_joint_z" pos="0 0 0" axis="0 0 1" type="slide" group="3" damping="0" /><geom name="pile0" size="0.0075 0.0075 0.0075" type="box" material="pile_mat" mass="0.01" /><site name="pile0" size="0.005 0.005 0.005" type="box" /></body><body name="pile1" pos="0 0 0"><joint name="pile1_joint_x" pos="0 0 0" axis="1 0 0" type="slide" group="3" damping="0" /><joint name="pile1_joint_y" pos="0 0 0" axis="0 1 0" type="slide" group="3" damping="0" /><joint name="pile1_joint_z" pos="0 0 0" axis="0 0 1" type="slide" group="3" damping="0" /><geom name="pile1" size="0.0075 0.0075 0.0075" type="box" material="pile_mat" mass="0.01" /><site name="pile1" size="0.005 0.005 0.005" type="box" /></body><body name="pile2" pos="0 0 0"><joint name="pile2_joint_x" pos="0 0 0" axis="1 0 0" type="slide" group="3" damping="0" /><joint name="pile2_joint_y" pos="0 0 0" axis="0 1 0" type="slide" group="3" damping="0" /><joint name="pile2_joint_z" pos="0 0 0" axis="0 0 1" type="slide" group="3" damping="0" /><geom name="pile2" size="0.0075 0.0075 0.0075" type="box" material="pile_mat" mass="0.01" /><site name="pile2" size="0.005 0.005 0.005" type="box" /></body><body name="pile3" pos="0 0 0"><joint name="pile3_joint_x" pos="0 0 0" axis="1 0 0" type="slide" group="3" damping="0" /><joint name="pile3_joint_y" pos="0 0 0" axis="0 1 0" type="slide" group="3" damping="0" /><joint name="pile3_joint_z" pos="0 0 0" axis="0 0 1" type="slide" group="3" damping="0" /><geom name="pile3" size="0.0075 0.0075 0.0075" type="box" material="pile_mat" mass="0.01" /><site name="pile3" size="0.005 0.005 0.005" type="box" /></body><body name="pile4" pos="0 0 0"><joint name="pile4_joint_x" pos="0 0 0" axis="1 0 0" type="slide" group="3" damping="0" /><joint name="pile4_joint_y" pos="0 0 0" axis="0 1 0" type="slide" group="3" damping="0" /><joint name="pile4_joint_z" pos="0 0 0" axis="0 0 1" type="slide" group="3" damping="0" /><geom name="pile4" size="0.0075 0.0075 0.0075" type="box" material="pile_mat" mass="0.01" /><site name="pile4" size="0.005 0.005 0.005" type="box" /></body><body name="pile5" pos="0 0 0"><joint name="pile5_joint_x" pos="0 0 0" axis="1 0 0" type="slide" group="3" damping="0" /><joint name="pile5_joint_y" pos="0 0 0" axis="0 1 0" type="slide" group="3" damping="0" /><joint name="pile5_joint_z" pos="0 0 0" axis="0 0 1" type="slide" group="3" damping="0" /><geom name="pile5" size="0.0075 0.0075 0.0075" type="box" material="pile_mat" mass="0.01" /><site name="pile5" size="0.005 0.005 0.005" type="box" /></body><body name="pile6" pos="0 0 0"><joint name="pile6_joint_x" pos="0 0 0" axis="1 0 0" type="slide" group="3" damping="0" /><joint name="pile6_joint_y" pos="0 0 0" axis="0 1 0" type="slide" group="3" damping="0" /><joint name="pile6_joint_z" pos="0 0 0" axis="0 0 1" type="slide" group="3" damping="0" /><geom name="pile6" size="0.0075 0.0075 0.0075" type="box" material="pile_mat" mass="0.01" /><site name="pile6" size="0.005 0.005 0.005" type="box" /></body><body name="pile7" pos="0 0 0"><joint name="pile7_joint_x" pos="0 0 0" axis="1 0 0" type="slide" group="3" damping="0" /><joint name="pile7_joint_y" pos="0 0 0" axis="0 1 0" type="slide" group="3" damping="0" /><joint name="pile7_joint_z" pos="0 0 0" axis="0 0 1" type="slide" group="3" damping="0" /><geom name="pile7" size="0.0075 0.0075 0.0075" type="box" material="pile_mat" mass="0.01" /><site name="pile7" size="0.005 0.005 0.005" type="box" /></body><body name="pile8" pos="0 0 0"><joint name="pile8_joint_x" pos="0 0 0" axis="1 0 0" type="slide" group="3" damping="0" /><joint name="pile8_joint_y" pos="0 0 0" axis="0 1 0" type="slide" group="3" damping="0" /><joint name="pile8_joint_z" pos="0 0 0" axis="0 0 1" type="slide" group="3" damping="0" /><geom name="pile8" size="0.0075 0.0075 0.0075" type="box" material="pile_mat" mass="0.01" /><site name="pile8" size="0.005 0.005 0.005" type="box" /></body><body name="pile9" pos="0 0 0"><joint name="pile9_joint_x" pos="0 0 0" axis="1 0 0" type="slide" group="3" damping="0" /><joint name="pile9_joint_y" pos="0 0 0" axis="0 1 0" type="slide" group="3" damping="0" /><joint name="pile9_joint_z" pos="0 0 0" axis="0 0 1" type="slide" group="3" damping="0" /><geom name="pile9" size="0.0075 0.0075 0.0075" type="box" material="pile_mat" mass="0.01" /><site name="pile9" size="0.005 0.005 0.005" type="box" /></body><body name="pile10" pos="0 0 0"><joint name="pile10_joint_x" pos="0 0 0" axis="1 0 0" type="slide" group="3" damping="0" /><joint name="pile10_joint_y" pos="0 0 0" axis="0 1 0" type="slide" group="3" damping="0" /><joint name="pile10_joint_z" pos="0 0 0" axis="0 0 1" type="slide" group="3" damping="0" /><geom name="pile10" size="0.0075 0.0075 0.0075" type="box" material="pile_mat" mass="0.01" /><site name="pile10" size="0.005 0.005 0.005" type="box" /></body><body name="pile11" pos="0 0 0"><joint name="pile11_joint_x" pos="0 0 0" axis="1 0 0" type="slide" group="3" damping="0" /><joint name="pile11_joint_y" pos="0 0 0" axis="0 1 0" type="slide" group="3" damping="0" /><joint name="pile11_joint_z" pos="0 0 0" axis="0 0 1" type="slide" group="3" damping="0" /><geom name="pile11" size="0.0075 0.0075 0.0075" type="box" material="pile_mat" mass="0.01" /><site name="pile11" size="0.005 0.005 0.005" type="box" /></body><body name="pile12" pos="0 0 0"><joint name="pile12_joint_x" pos="0 0 0" axis="1 0 0" type="slide" group="3" damping="0" /><joint name="pile12_joint_y" pos="0 0 0" axis="0 1 0" type="slide" group="3" damping="0" /><joint name="pile12_joint_z" pos="0 0 0" axis="0 0 1" type="slide" group="3" damping="0" /><geom name="pile12" size="0.0075 0.0075 0.0075" type="box" material="pile_mat" mass="0.01" /><site name="pile12" size="0.005 0.005 0.005" type="box" /></body><body name="pile13" pos="0 0 0"><joint name="pile13_joint_x" pos="0 0 0" axis="1 0 0" type="slide" group="3" damping="0" /><joint name="pile13_joint_y" pos="0 0 0" axis="0 1 0" type="slide" group="3" damping="0" /><joint name="pile13_joint_z" pos="0 0 0" axis="0 0 1" type="slide" group="3" damping="0" /><geom name="pile13" size="0.0075 0.0075 0.0075" type="box" material="pile_mat" mass="0.01" /><site name="pile13" size="0.005 0.005 0.005" type="box" /></body><body name="pile14" pos="0 0 0"><joint name="pile14_joint_x" pos="0 0 0" axis="1 0 0" type="slide" group="3" damping="0" /><joint name="pile14_joint_y" pos="0 0 0" axis="0 1 0" type="slide" group="3" damping="0" /><joint name="pile14_joint_z" pos="0 0 0" axis="0 0 1" type="slide" group="3" damping="0" /><geom name="pile14" size="0.0075 0.0075 0.0075" type="box" material="pile_mat" mass="0.01" /><site name="pile14" size="0.005 0.005 0.005" type="box" /></body></worldbody><asset><texture builtin="flat" type="2d" name="pile_tex" height="32" width="32" /><material name="pile_mat" specular="0.5" shininess="0.2" reflectance="0" texture="pile_tex" /></asset></mujoco>